Workbook
Name ComplianceList: OFFSET('[1]8. Control DB'!$D$6,0,0,COUNTA('[1]8. Control DB'!$D$6:$D$25),1)
Name ComplianceList: OFFSET('[2]8. Control DB'!$D$6,0,0,COUNTA('[2]8. Control DB'!$D$6:$D$25),1)
Name ControlsPerEnv: OFFSET('[1]9. Lists & Calcs (Hidden)'!$B$81,0,0,5-COUNTBLANK('[1]9. Lists & Calcs (Hidden)'!$B$81:$B$85),1)
Name ControlsPerEnv: OFFSET('[2]9. Lists & Calcs (Hidden)'!$B$81,0,0,5-COUNTBLANK('[2]9. Lists & Calcs (Hidden)'!$B$81:$B$85),1)
Name ControlsPerEnv2: OFFSET('[1]9. Lists & Calcs (Hidden)'!$C$81,0,0,5-COUNTBLANK('[1]9. Lists & Calcs (Hidden)'!$C$81:$C$85),1)
Name ControlsPerEnv2: OFFSET('[2]9. Lists & Calcs (Hidden)'!$C$81,0,0,5-COUNTBLANK('[2]9. Lists & Calcs (Hidden)'!$C$81:$C$85),1)
Name ControlsPerOb: OFFSET('[1]9. Lists & Calcs (Hidden)'!$B$88,0,0,10-COUNTBLANK('[1]9. Lists & Calcs (Hidden)'!$B$88:$B$97),1)
Name ControlsPerOb: OFFSET('[2]9. Lists & Calcs (Hidden)'!$B$88,0,0,10-COUNTBLANK('[2]9. Lists & Calcs (Hidden)'!$B$88:$B$97),1)
Name ControlsPerOb2: OFFSET('[1]9. Lists & Calcs (Hidden)'!$C$88,0,0,10-COUNTBLANK('[1]9. Lists & Calcs (Hidden)'!$C$88:$C$97),1)
Name ControlsPerOb2: OFFSET('[2]9. Lists & Calcs (Hidden)'!$C$88,0,0,10-COUNTBLANK('[2]9. Lists & Calcs (Hidden)'!$C$88:$C$97),1)
Name EnvironmentList: OFFSET('[1]9. Lists & Calcs (Hidden)'!$D$8,0,0,6-COUNTBLANK('[1]9. Lists & Calcs (Hidden)'!$D$8:$D$13),1)
Name EnvironmentList: OFFSET('[2]9. Lists & Calcs (Hidden)'!$D$8,0,0,6-COUNTBLANK('[2]9. Lists & Calcs (Hidden)'!$D$8:$D$13),1)
Name InitiativeList: OFFSET('[3]5. Initiative List'!$C$6,0,0,COUNTA('[3]5. Initiative List'!$C$6:$C$105),1)
Name InitiativeList: OFFSET('[4]5. Initiative List'!$C$6,0,0,COUNTA('[4]5. Initiative List'!$C$6:$C$105),1)
Name InitiativeNames: '5. Initiative List'!$C$6:$C$45
Name ObsPerEnv: OFFSET('[1]9. Lists & Calcs (Hidden)'!$B$58,0,0,5-COUNTBLANK('[1]9. Lists & Calcs (Hidden)'!$B$58:$B$62),1)
Name ObsPerEnv: OFFSET('[2]9. Lists & Calcs (Hidden)'!$B$58,0,0,5-COUNTBLANK('[2]9. Lists & Calcs (Hidden)'!$B$58:$B$62),1)
Name ObsPerEnv2: OFFSET('[1]9. Lists & Calcs (Hidden)'!$C$58,0,0,5-COUNTBLANK('[1]9. Lists & Calcs (Hidden)'!$C$58:$C$62),1)
Name ObsPerEnv2: OFFSET('[2]9. Lists & Calcs (Hidden)'!$C$58,0,0,5-COUNTBLANK('[2]9. Lists & Calcs (Hidden)'!$C$58:$C$62),1)

Sheet 1. Introduction
B2: iSSDLC Capabilities Assessment
B3: Description The purpose of the iSSDLC Capability Assessment is to assess the maturity of the organization's secure software delivery lifecycle. The assessment focuses on the organization's current application security practices and maturity levels, identifying their target state, and developing a roadmap to achieve their desired state. Use the tool with the associated project blueprint, Develop a Strategic Plan for Intelligent Application Security and its tools and templates.
B6: For acceptable use of this tool, refer to Info-Tech's Terms of Use. These documents are intended to supply general information only, not specific professional or personal advice, and are not intended to be used as a substitute for any kind of professional advice. Use this document either in whole or in part as a basis and guide for document creation. To customize this document with corporate marks and titles, simply replace the Info-Tech information in the Header and Footer fields of this document.

Sheet 2. Setup
B2: Tool Configuration
B3: The settings on this tab will configure the tool for your organization. You can enter: - The security alignment with business benefit and additional application security benefits, which inform the prioritization on Tab 6. - Initiative cost and benefits estimates, which populate the cost-benefit tables and menus on Tab 6. - Full-time equivalent hours, which inform the cost and effort calculations on Tab 6. - The roadmap start year, which informs the start date on the Tab 7. Review the instructions for each setting to determine how to modify it.
C7: Initiative Cost Estimation Use this section to provide initial cost estimate values for the initiative prioritization on Tab 6. In column E below (Range), enter appropriate ranges for high, medium, and low costs and efforts to be used to do costing estimations on initiatives. In column F below (Average), enter appropriate averages for each range; these averages will be used to calculate total costs for your application security roadmap.
C8: Initiative Costs for Estimation | E8: Range | G8: Average
C9: Initial Cost | D9: High | E9: >$100K | G9: 120000
D10: Medium | E10: $10K-$100K | G10: 50000
D11: Low | E11: <$10,000 | G11: 5000
C12: Ongoing Cost (annual) | D12: High | E12: >$100K | G12: 120000
D13: Medium | E13: $10K-$100K | G13: 50000
D14: Low | E14: <$10,000 | G14: 5000
C15: Initial Staffing in Hours | D15: High | E15: >160 Hours | G15: 240
D16: Medium | E16: 40-160 Hours | G16: 120
D17: Low | E17: <40 Hours | G17: 30
C18: Ongoing Staffing in Full-Time Equivalents (FTEs) | D18: High | E18: >0.5 FTE | G18: 0.5
D19: Medium | E19: 0.1-0.5 FTE | G19: 0.25
D20: Low | E20: <0.1 FTE | G20: 0.05
C24: Security Initiative Benefit Use this section to define menu options for initiative prioritization on Tab 6. In column E below (Description), you may modify the descriptions of the high, medium, and low criteria that will be used in the benefit estimations on initiatives. The benefit estimation includes alignment with business benefit in terms of supporting business opportunities, along with security benefit in terms of mitigating priority threats. Further selection of these benefits will be captured on Tab 3.
C25: Initiative Benefits for Estimation | E25: Description
C26: Alignment With Business Benefit | D26: High | E26: Supports multiple priority opportunities
D27: Medium | E27: Supports a priority opportunity
D28: Low | E28: Other
C29: Security Benefit | D29: High | E29: Mitigates multiple priority threats
D30: Medium | E30: Mitigates a priority threat
D31: Low | E31: Foundational good practice
C35: FTE Equivalent Use this section to define FTE values. Enter the number of hours per year that your organization uses to define a full-time equivalent (FTE). This number will be used to provide total effort requirements for initiatives on Tab 6.
C36: Full-Time Equivalent Hours | D36: 1960
C41: Roadmap Start Year Use this number to define the start year for the roadmap on Tab 7. Enter the starting year for your application security roadmap.
C42: Roadmap Start Year | D42: 2026

Sheet 3. Goals
B2: Goals
B4: The settings on this tab will configure the tool for your organization. You will define your primary business opportunities, security threats, and metrics, that will assist in the prioritization of application security capability initiatives.
G5: Business Opportunity | H5: Definition
C6: Priority Business Opportunities | G6: =IF('9. List & Calc'!C15="", "", '9. List & Calc'!C15) -> Monetize data and services through premium APIs. | H6: =IF('9. List & Calc'!D15="", "", '9. List & Calc'!D15) -> Safely enable new revenue streams for your data and services by providing secure application programming interfaces (API) capabilities for your customers.
C7: Use this section to determine your primary business opportunities for your organization. Leverage the list of business opportunities in the table on the right to select up to three business opportunities that should be considered when implementing the iSSDLC. | G7: =IF('9. List & Calc'!C16="", "", '9. List & Calc'!C16) -> Faster time to value for new products. | H7: =IF('9. List & Calc'!D16="", "", '9. List & Calc'!D16) -> Bring new products and services to market faster by collapsing lengthy security checkpoints.
C8: Priority Business Opportunities | G8: =IF('9. List & Calc'!C17="", "", '9. List & Calc'!C17) -> Reduce compliance costs and enter new regulated markets faster. | H8: =IF('9. List & Calc'!D17="", "", '9. List & Calc'!D17) -> Cut audit preparation effort, turning compliance from a go/no‑go barrier into a predictable, budgeted line item when entering new regulated markets.
C9: Faster time to value for new products. | G9: =IF('9. List & Calc'!C18="", "", '9. List & Calc'!C18) -> Reduce cyber‑insurance premiums and borrowing costs. | H9: =IF('9. List & Calc'!D18="", "", '9. List & Calc'!D18) -> Verified controls translate directly into lower insurance rates and better debt covenants.
C10: Reduce cyber‑insurance premiums and borrowing costs. | G10: =IF('9. List & Calc'!C19="", "", '9. List & Calc'!C19) -> Accelerate AI & advanced analytics initiatives. | H10: =IF('9. List & Calc'!D19="", "", '9. List & Calc'!D19) -> Ensure models and applications do not leak PII, allowing unrestricted exploitation of high‑value datasets.
C11: Complete technology M&A integrations faster. | G11: =IF('9. List & Calc'!C20="", "", '9. List & Calc'!C20) -> Complete technology M&A integrations faster. | H11: =IF('9. List & Calc'!D20="", "", '9. List & Calc'!D20) -> Provide instant visibility into inherited risk, avoiding lengthy manual code reviews that stall deal synergies.
G12: =IF('9. List & Calc'!C21="", "", '9. List & Calc'!C21) -> Increase uptime for digital revenue channels. | H12: =IF('9. List & Calc'!D21="", "", '9. List & Calc'!D21) -> Maintain customer transactions during security incidents, protecting revenue and brand in real time.
G13: =IF('9. List & Calc'!C22="", "", '9. List & Calc'!C22) -> Scale partner ecosystems without expanding the attack surface. | H13: =IF('9. List & Calc'!D22="", "", '9. List & Calc'!D22) -> Add partners rapidly while keeping every integration compartmentalized and auditable.
G14: =IF('9. List & Calc'!C23="", "", '9. List & Calc'!C23) -> Strengthen brand loyalty and customer trust. | H14: =IF('9. List & Calc'!D23="", "", '9. List & Calc'!D23) -> Build digital trust by safeguarding customer journeys that shape digital experience and perception.
G16: Security Threats | H16: Importance From Executive Level
C17: Priority Security Threats | G17: =IF('9. List & Calc'!C27="", "", '9. List & Calc'!C27) -> Software supply‑chain compromise. | H17: =IF('9. List & Calc'!D27="", "", '9. List & Calc'!D27) -> Reduce risk of business impacts due to compromised software supply chains.
C18: Use this section to identify the top application security threats to the organization based on its importance to executives. Leverage the list of security threats in the table on the right to select up to three security threats as primary drivers for the iSSDLC. | G18: =IF('9. List & Calc'!C28="", "", '9. List & Calc'!C28) -> Mass credential‑stuffing and account takeover. | H18: =IF('9. List & Calc'!D28="", "", '9. List & Calc'!D28) -> Protect the company’s revenue channels and brand trust by preventing fraudulent transactions.
C19: Priority Security Threats | G19: =IF('9. List & Calc'!C29="", "", '9. List & Calc'!C29) -> Business‑logic abuse through exposed APIs. | H19: =IF('9. List & Calc'!D29="", "", '9. List & Calc'!D29) -> Turn APIs from a liability into a controlled asset, preserving digital revenues and preventing competitor access to your data.
C20: Business‑logic abuse through exposed APIs. | G20: =IF('9. List & Calc'!C30="", "", '9. List & Calc'!C30) -> Ransomware beachhead via vulnerable web apps. | H20: =IF('9. List & Calc'!D30="", "", '9. List & Calc'!D30) -> Shrink attacks window from weeks to hours, denying cyber criminals the foothold they need to disrupt revenue‑producing systems.
C21: Ransomware beachhead via vulnerable web apps. | G21: =IF('9. List & Calc'!C31="", "", '9. List & Calc'!C31) -> Prolonged service outage due to zero-day attacks. | H21: =IF('9. List & Calc'!D31="", "", '9. List & Calc'!D31) -> Keep critical digital services online even when patching is impossible, preserving daily revenue and market confidence.
C22: Insider misuse or privileged‑user abuse of critical functions. | G22: =IF('9. List & Calc'!C32="", "", '9. List & Calc'!C32) -> Sensitive‑data leakage in AI‑enabled apps. | H22: =IF('9. List & Calc'!D32="", "", '9. List & Calc'!D32) -> Enable aggressive AI adoption without triggering privacy fines or IP loss, safeguarding future growth bets.
G23: =IF('9. List & Calc'!C33="", "", '9. List & Calc'!C33) -> Insider misuse or privileged‑user abuse of critical functions. | H23: =IF('9. List & Calc'!D33="", "", '9. List & Calc'!D33) -> Turn insider risk into a detectable, auditable event, limiting impact and demonstrating diligence to shareholders.
G24: =IF('9. List & Calc'!C34="", "", '9. List & Calc'!C34) -> Quantum computing renders legacy encryption obsolete. | H24: =IF('9. List & Calc'!D34="", "", '9. List & Calc'!D34) -> Safeguard crown jewel data when current generation encryption fails under attack by quantum computers.
G25: =IF('9. List & Calc'!C35="", "", '9. List & Calc'!C35) -> Nation-state attack on critical infrastructure via sleeper accounts. | H25: =IF('9. List & Calc'!D35="", "", '9. List & Calc'!D35) -> Protect critical infrastructure from advanced persistent threats using long-term account compromise.
G27: Security Metrics | H27: How to Measure
C28: Priority Security Metrics | G28: =IF('9. List & Calc'!C38="", "", '9. List & Calc'!C38) -> Mean Time to Remediate (MTTR) Critical Vulnerabilities. | H28: =IF('9. List & Calc'!D38="", "", '9. List & Calc'!D38) -> Average number of days from detection to remediation for CVEs rated critical or high (track via SAST/DAST/SCA tools + ticketing system).
C29: Use this section to identify the security metrics you would want to measure for your application security modernization initiatives. Leverage the list of security metrics in the table on the right to select up to four security metrics. | G29: =IF('9. List & Calc'!C39="", "", '9. List & Calc'!C39) -> Percentage of Third-Party Components Without Known Vulnerabilities. | H29: =IF('9. List & Calc'!D39="", "", '9. List & Calc'!D39) -> Count of external libraries/packages scanned by SCA tools with 0 known CVEs; total components used.
C30: Priority Security Metrics | G30: =IF('9. List & Calc'!C40="", "", '9. List & Calc'!C40) -> Credential Stuffing Detection Rate. | H30: =IF('9. List & Calc'!D40="", "", '9. List & Calc'!D40) -> Number of credential stuffing attempts detected per month, tracked via WAF logs, SIEM, or identity provider analytics.
C31: Time to Patch Zero-Day Vulnerabilities | G31: =IF('9. List & Calc'!C41="", "", '9. List & Calc'!C41) -> Security Coverage in CI/CD Pipeline. | H31: =IF('9. List & Calc'!D41="", "", '9. List & Calc'!D41) -> % of CI/CD jobs that include SAST, DAST, SCA, secrets scanning, or IaC scanning.
C32: Percentage of Third-Party Components Without Known Vulnerabilities | G32: =IF('9. List & Calc'!C42="", "", '9. List & Calc'!C42) -> Time to Patch Zero-Day Vulnerabilities. | H32: =IF('9. List & Calc'!D42="", "", '9. List & Calc'!D42) -> Measure time from vendor disclosure of zero-day to patch deployment in production.
C33: Insider Threat Detections | G33: =IF('9. List & Calc'!C43="", "", '9. List & Calc'!C43) -> Percentage of APIs With Business Logic Testing. | H33: =IF('9. List & Calc'!D43="", "", '9. List & Calc'!D43) -> Number of APIs with completed business logic abuse tests; total APIs in production.
C34: % of Business Applications with Risk-Based Classification | G34: =IF('9. List & Calc'!C44="", "", '9. List & Calc'!C44) -> Data Exposure Events From AI Workloads. | H34: =IF('9. List & Calc'!D44="", "", '9. List & Calc'!D44) -> Count of security events involving PII or sensitive data leaks from AI features, tracked via DLP tools or incident logs.
G35: =IF('9. List & Calc'!C45="", "", '9. List & Calc'!C45) -> Quantum-Resilience Readiness. | H35: =IF('9. List & Calc'!D45="", "", '9. List & Calc'!D45) -> Percent of crypto assets inventoried and evaluated for post-quantum readiness.
G36: =IF('9. List & Calc'!C46="", "", '9. List & Calc'!C46) -> Insider Threat Detections. | H36: =IF('9. List & Calc'!D46="", "", '9. List & Calc'!D46) -> Number of suspicious privileged actions or misuse attempts logged and investigated.
G37: =IF('9. List & Calc'!C47="", "", '9. List & Calc'!C47) -> Average Time to Enable Secure Partner Integrations. | H37: =IF('9. List & Calc'!D47="", "", '9. List & Calc'!D47) -> Days from partner onboarding request to secure API/key deployment and access enablement.
G38: =IF('9. List & Calc'!C48="", "", '9. List & Calc'!C48) -> Percent of Business Applications With Risk-Based Classification. | H38: =IF('9. List & Calc'!D48="", "", '9. List & Calc'!D48) -> Business apps tagged by sensitivity and risk level; total app inventory.
G39: =IF('9. List & Calc'!C49="", "", '9. List & Calc'!C49) -> Percent of Open, Premium APIs With Security Controls. | H39: =IF('9. List & Calc'!D49="", "", '9. List & Calc'!D49) -> APIs exposed for partner/customer access that implement authN/Z, rate limiting, logging, threat detection.
G40: =IF('9. List & Calc'!C50="", "", '9. List & Calc'!C50) -> Secure AI/ML Development Lifecycle Coverage. | H40: =IF('9. List & Calc'!D50="", "", '9. List & Calc'!D50) -> Percent of AI/ML projects that completed threat modeling, data protection review, and adversarial testing.
G41: =IF('9. List & Calc'!C51="", "", '9. List & Calc'!C51) -> Incident Response Drill Frequency & Readiness Score | H41: =IF('9. List & Calc'!D51="", "", '9. List & Calc'!D51) -> Number of tabletop or red team exercises run annually; scoring based on containment, comms, and recovery effectiveness.
G42: =IF('9. List & Calc'!C52="", "", '9. List & Calc'!C52) -> Application Uptime With Security Events | H42: =IF('9. List & Calc'!D52="", "", '9. List & Calc'!D52) -> Percent of time core revenue-generating applications maintained availability despite security alerts/incidents.

Sheet 4. Capabilities Assessment
B2: Application Security Capabilities Assessment
B4: Review each of the iSSDLC capabilities defined in column D. Then: 1) Enter the current state of the capability in column K, and optionally include comments about the current state in column L. 2) Define your target state for the capability in column M. 3) If you plan to improve the capability, use the drop-down list in column N to indicate the name of the planned initiative for this work. If you need to add or change initiatives, you can do so on tab 4. Columns O and P provide basic information on some of the tools available to improve each capability. Visit softwarereviews.com for more information on available technology.
C5: Maturity Level | D5: Definition | G5: Prioritization Legend:
C6: Manual | D6: Capability is ad-hoc and entirely human-driven. Little or no tooling; success depends on individual effort and group knowledge. | G6: Capability is aligned with three or more opportunities/threats
C7: Assisted | D7: Basic tools, checklists, or templates help humans find issues or follow best practices, but people still decide and perform every task. | G7: Capability is aligned with two opportunities/threats
C8: Orchestrated | D8: Tool-driven, multi-step workflows carry out security tasks end-to-end (e.g. scans → PRs → tests) while humans provide oversight and final approval at defined risk gates. | G8: Capability is aligned with an opportunity or threat
C9: Automated | D9: Analytics and AI adapt controls continuously, remediate most routine issues without waiting for people, and escalate only edge cases. Security processes run largely hands-free.
C10: Autonomous | D10: Humans set strategy and ethics. AI agents operate, learn, and optimize security end-to-end with minimal human input. The iSSDLC capability proves compliance on its own.
B12: Capabilities Assessment | F12: Example capability description per maturity level
B13: iSSDLC Phases | C13: ID | D13: Capability | E13: Definition | F13: L1 – Manual | G13: L2 – Assisted | H13: L3 – Orchestrated | I13: L4 – Automated | J13: L5 – Autonomous | K13: Current State | L13: Current State Comments | M13: Target State | N13: Initiative | O13: Example Tools | P13: Example Vendors
B14: Analyze & Design | C14: AD.01 | D14: Security Requirements Definition | E14: Document explicit security objectives and control requirements early. | F14: Unstructured requirements verbally shared, rarely documented. | G14: Checklist templates guide writing, still manual approval. | H14: Workflow triggers requirement forms; stakeholders approve via portal. | I14: Analytics map requirements to controls automatically; gaps flagged instantly. | J14: AI agents evolve requirements, verify compliance continuously, report autonomously. | K14: L2 – Assisted | M14: L3 – Orchestrated | N14: Implement Secure SDLC Requirements Gathering Templates | O14: Requirements management tools, Secure SDLC platforms | P14: Jira Security, Azure Boards, IriusRisk, ThreatSpec
C15: AD.02 | D15: Threat Modeling | E15: Systematically identify and prioritize threats and mitigations. | F15: Threats brainstormed informally, inconsistent, undocumented. | G15: Templates guide threat lists; analysts decide mitigations. | H15: Orchestration runs model generation; reviewers approve high-risk issues. | I15: AI updates threat models continuously; auto-assigns mitigations. | J15: Agents predict emerging threats, deploy mitigations proactively. | K15: L3 – Orchestrated | M15: L4 – Automated | N15: Deploy Threat Modeling Automation Tools (e.g., ThreatSpec, IriusRisk) | O15: Threat modeling tools | P15: Microsoft TMT, IriusRisk, ThreatModeler, OWASP Threat Dragon
C16: AD.03 | D16: Secure Architecture Design | E16: Embed security principles in system architecture. | F16: Architecture decisions ignore security or rely on memories. | G16: Reference checklists consulted; engineers manually embed controls. | H16: Design workflow enforces pattern libraries and security gate approvals. | I16: Automated reasoning suggests secure patterns, validates architecture. | J16: Self-optimizing architecture refactors for emerging security objectives. | K16: L1 – Manual | M16: L1 – Manual | N16: Establish Secure Architecture Review Board | O16: Design validation & architecture modeling tools | P16: AWS Well‑Architected Tool, IBM Security Blueprint, ArchiMate plug‑ins
C17: AD.04 | D17: Zero Trust Architecture | E17: Develop an architecture with continuous identity, device, and context verification. | F17: Perimeter defenses only; trust internal network implicitly. | G17: Scripts verify identities manually for critical paths. | H17: Workflow provisions micro-segmentation; approvals enforce least privilege. | I17: Adaptive policies enforced automatically across identity, device, context. | J17: Autonomous system continuously evaluates trust, reconfigures architecture. | K17: L2 – Assisted | M17: L3 – Orchestrated | N17: Establish Secure Architecture Review Board | O17: Identity & access management, micro-segmentation | P17: Zscaler, Okta, Cloudflare Zero Trust, Cisco Duo
C18: AD.05 | D18: Secure AI/ML Design | E18: Protect ML and AI models and components. | F18: Data sources unverified; lineage undocumented. | G18: Scripts track datasets; manual integrity checks. | H18: Workflows enforce provenance tagging; risk gate reviews. | I18: Analytics detect poisoned data automatically. | J18: Agents curate datasets, verify compliance continuously. | K18: L2 – Assisted | M18: L3 – Orchestrated | N18: Establish Secure Architecture Review Board | O18: ML security platforms, data masking & encryption tools | P18: Azure ML, Google Vertex AI, IBM watsonx.governance, Protect AI
C19: AD.06 | D19: AI/ML Training Data Collection Security | E19: Ensure training dataset provenance, integrity, and compliance. | F19: Scraped data stored unvalidated. | G19: Manual sample review checklist. | H19: Pipeline verifies schema & hashes. | I19: Classifier flags poisoned/toxic data. | J19: Agent curates, labels, sanitizes continuously. | K19: L1 – Manual | M19: L4 – Automated | N19: Implement Secure AI/ML Design Controls & Data Lineage Tracking | O19: Data lineage tools, access governance platforms | P19: Great Expectations, DataHub, Immuta, LakeFS
C20: AD.07 | D20: Secure Design Review & Assurance | E20: Independent verification of design to meet security needs. | F20: Occasional informal design reviews by security champion. | G20: Checklist-based reviews scheduled; findings tracked manually. | H20: Orchestrated ticketing assigns reviewers, collects evidence automatically. | I20: AI analyzes designs, flags violations, autogenerates reports. | J20: Agents certify design compliance continuously, adapt controls. | K20: L2 – Assisted | M20: L2 – Assisted | N20: Secure Design Improvements | O20: SDLC review checklists, architecture scanning | P20: Confluence templates, Lucidchart, IriusRisk reviews
B21: Build | C21: BU.01 | D21: Secure Coding Practices & Training | E21: Apply security coding guidelines and train developers on security best practices. | F21: Developers unaware of secure coding, local knowledge only. | G21: Static checklist; yearly classroom training. | H21: Integrated LMS tracks modules, reminders via pipelines. | I21: AI personalizes just-in-time training suggestions in IDE. | J21: Autonomous coach agents guide coding, update lessons continuously. | K21: L2 – Assisted | M21: L4 – Automated | N21: Train Developers on Secure Coding Practices (OWASP Top 10) | O21: Developer education platforms, coding policy engines | P21: Semgrep, SonarLint, GitHub Copilot, OWASP ASVS
C22: BU.02 | D22: Secure Code Review & Static Analysis | E22: Use peer and automated review to find code flaws. | F22: Peer reviews sporadic; no tooling. | G22: Static scanners run manually before merge. | H22: Pipeline orchestrates scans, opens pull-request issues. | I22: AI triages findings, auto-fixes common patterns. | J22: Agents rewrite code securely, prove correctness. | K22: L2 – Assisted | M22: L4 – Automated | N22: Integrate SAST Tools into CI Pipeline | O22: SAST tools | P22: GitHub CodeQL, SonarQube, Checkmarx, Fortify
C23: BU.03 | D23: Software Supply Chain Security | E23: Manage risk from third‑party code & builds. | F23: Third-party components managed ad-hoc. | G23: Dependency lists maintained with occasional vulnerability checks. | H23: Automated SBOM generation and orchestrated patch workflows. | I23: Continuous monitoring, AI blocks vulnerable packages. | J23: Agents predict risks, swap dependencies proactively. | K23: L1 – Manual | M23: L1 – Manual | N23: Automate Software Composition Analysis & Supply Chain Scanning | O23: Software composition analysis (SCA) tools | P23: Snyk, Anchore, Chainguard, GitGuardian, Sigstore
C24: BU.04 | D24: Secure Build & CI/CD Pipeline | E24: Harden and validate build & release pipelines. | F24: Build scripts shared manually; integrity unchecked. | G24: Basic pipeline with manual security steps. | H24: Orchestration runs security stages automatically; approvals required. | I24: Telemetry adjusts pipeline security controls dynamically. | J24: Self-healing pipeline enforces, optimizes security continuously. | K24: L2 – Assisted | M24: L3 – Orchestrated | N24: Enhance CI/CD Pipelines with Secrets Scanning & Signing Tools | O24: Secure CI/CD orchestration platforms | P24: GitHub Actions, GitLab CI, Jenkins, CircleCI OIDC
C25: BU.05 | D25: Secure Version Control & Repository Management | E25: Protect code repositories from unauthorized or malicious changes. | F25: Open permissions; commits unaudited. | G25: Protected branches; manual code-owner reviews. | H25: Workflows enforce signed commits and permission gates. | I25: AI detects malicious commits and reverts automatically. | J25: Agents manage repository policies, optimize permissions autonomously. | K25: L1 – Manual | M25: L3 – Orchestrated | O25: VCS platforms with security features | P25: GitHub Enterprise, GitLab Ultimate, Bitbucket, Gitea + GPG
C26: BU.06 | D26: Secrets Management in Development | E26: Handle credentials & keys safely in development. | F26: Secrets hard-coded in source. | G26: Environment variables used with manual rotation. | H26: Central vault orchestrated via pipelines. | I26: Automated rotation and injection by AI controller. | J26: Agents optimize secret usage, eliminate unnecessary credentials. | K26: L3 – Orchestrated | M26: L4 – Automated | N26: Enhance CI/CD Pipelines with Secrets Scanning & Signing Tools | O26: Secret scanning & vaulting tools | P26: HashiCorp Vault, AWS Secrets Manager, Azure Key Vault, Doppler
B27: Test | C27: TE.01 | D27: Automated Security Testing | E27: Run automated security testing (i.e. DAST, IAST) against applications. | F27: No automated tests; manual checks occasional. | G27: DAST runs triggered manually. | H27: Pipeline orchestrates suite across environments. | I27: AI prioritizes findings, auto-creates tickets. | J27: Agents auto-remediate issues and retest continuously. | K27: L3 – Orchestrated | M27: L5 – Autonomous | N27: Integrate SAST Tools into CI Pipeline | O27: CI-integrated security scanners (SAST/DAST/IAST) | P27: OWASP ZAP, Burp Suite Enterprise, Nessus, Synopsys Black Duck
C28: TE.02 | D28: Penetration Testing & Red Teaming | E28: Human adversarial testing for deep flaws. | F28: Rare, informal penetration tests. | G28: Annual external engagements with manual scope. | H28: Red-team exercises scheduled, findings integrated into backlog. | I28: Automated attack simulations run continuously. | J28: Adaptive adversarial agents test and harden systems autonomously. | K28: L2 – Assisted | M28: L3 – Orchestrated | N28: Establish Fuzzing and Red Team Engagement Programs | O28: Penetration testing platforms, red team kits | P28: Burp Pro, Kali Linux, Metasploit, Cobalt Strike, Randori
C29: TE.03 | D29: Fuzz & Chaos Testing | E29: Test with mutation and random input to provoke faults. | F29: Open-source fuzzers executed manually on ad-hoc basis. | G29: Fuzzers executed manually on a set schedule. | H29: Pipeline orchestrates fuzz jobs on targets. | I29: AI selects inputs and monitors impact automatically. | J29: Agents generate adversarial inputs and self-heal discovered weaknesses. | K29: L2 – Assisted | M29: L3 – Orchestrated | N29: Establish Fuzzing and Red Team Engagement Programs | O29: Fuzz testing engines | P29: AFL++, libFuzzer, Mayhem, Synopsys Defensics
C30: TE.04 | D30: Security Requirements Validation | E30: Prove system meets security requirements. | F30: Validation performed manually, inconsistently. | G30: Test scripts created manually to prove requirements. | H30: Orchestrated tests executed; results reviewed. | I30: AI correlates results to requirements and auto-flags failures. | J30: Agents continuously verify requirements and adjust controls proactively. | K30: L1 – Manual | M30: L2 – Assisted | N30: Implement Secure SDLC Requirements Gathering Templates | O30: Test automation + policy validation tools | P30: Jama Connect, Zephyr, Azure Test Plans, qTest
C31: TE.05 | D31: Secure Test Environments & Data Management | E31: Isolate test environments and protect data used for testing. | F31: Shared environments; test data unsecured. | G31: Manual masking, segregated environments limited. | H31: Workflows provision isolated, masked datasets automatically. | I31: AI monitors leaks and cleans environments on completion. | J31: Agents orchestrate secure environments with assured data governance. | K31: N/A | M31: L1 – Manual | O31: Test data masking/anonymization, sandboxing | P31: Delphix, Tonic.ai, Docker, K8s namespaces
B32: Deploy | C32: DE.01 | D32: Secure Deployment & Infrastructure‑as‑Code (IaC) | E32: Ensure infrastructure definitions and live configurations are securely authored, validated, deployed, and maintained. | F32: Scripts and IaC unmanaged; configs applied manually, insecure drift. | G32: Checklists and basic linters guide IaC; manual deployment approvals. | H32: CI/CD pipelines scan IaC and enforce configs and gate releases. | I32: AI auto-fixes IaC, deploys securely and remediates configuration drift. | J32: Agents self-generate infrastructure, optimize deployments, and prove compliance continuously. | K32: L4 – Automated | M32: L5 – Autonomous | O32: Deployment platforms with policy enforcement | P32: Ansible, Chef, Puppet, Terraform + Sentinel
C33: DE.02 | D33: Container & Orchestrator Security | E33: Secure images, runtime, and orchestration. | F33: Images built locally; security unchecked. | G33: Manual scans of container images. | H33: Pipeline enforces base image policies, orchestrator hardening. | I33: AI monitors runtime anomalies, auto-quarantines containers. | J33: Autonomous platform rebuilds images, mitigates threats pre-emptively. | K33: L1 – Manual | M33: L3 – Orchestrated | N33: Implement IaC and Container Security Scanning | O33: Container security platforms | P33: Aqua, Prisma Cloud, Sysdig Secure, Kubescape
C34: DE.03 | D34: Policy‑as‑Code (PaC) Deployment | E34: Encode and enforce policies as code. | F34: Policies documented offline; enforced manually. | G34: Scripts check policies on demand. | H34: PaC integrated into pipeline, gate approvals. | I34: Analytics tune policies; policies auto-enforced across environments. | J34: Agents evolve policies, verify adherence continuously. | K34: L2 – Assisted | M34: L4 – Automated | N34: Adopt Policy-as-Code for Automated Security Governance | O34: Policy engines for infrastructure & pipelines | P34: Open Policy Agent, Styra DAS, Kyverno, Sentinel
C35: DE.04 | D35: Artifact Signing & Provenance | E35: Cryptographically sign and attest artifacts. | F35: Builds unsigned; origin uncertain. | G35: Signing performed manually for releases. | H35: Workflow signs artifacts, stores provenance metadata. | I35: AI validates signatures and blocks tampered artifacts. | J35: Agents manage cryptographic materials and attest supply chain automatically. | K35: L1 – Manual | M35: L1 – Manual | N35: Enhance CI/CD Pipelines with Secrets Scanning & Signing Tools | O35: Software artifact attestation tools | P35: Sigstore/cosign, Notary v2, JFrog Artifactory, in‑toto
C36: DE.05 | D36: Deployment Security Gates & Reviews | E36: Automated approval gates for release risk. | F36: Releases happen without security approval. | G36: Manual gate checklists before deployment. | H36: Orchestrated approval gates integrate risk scores. | I36: AI evaluates risk, approves low-risk releases instantly. | J36: Autonomous governance continuously governs release readiness. | K36: L5 – Autonomous | M36: L5 – Autonomous | N36: Adopt Policy-as-Code for Automated Security Governance | O36: CI/CD approval gates, release compliance | P36: Spinnaker, Argo CD, LaunchDarkly, Harness
B37: Operate & Maintain | C37: OM.01 | D37: Security Monitoring & Threat Detection | E37: Monitor applications in operation for security threats. | F37: Minimal logging; alerts reactive only. | G37: Basic dashboards with manual alert triage. | H37: Orchestrated SIEM pipelines aggregate, correlate events. | I37: AI detects anomalies and triggers playbooks automatically. | J37: Agents predict attacks and auto-mitigate in real-time. | K37: L4 – Automated | M37: L5 – Autonomous | N37: Deploy Centralized Security Monitoring and Threat Detection Tools | O37: Cloud security monitoring & SIEM | P37: Splunk, Elastic Security, CrowdStrike, Datadog SIEM, Microsoft Sentinel
C38: OM.02 | D38: Incident Response & Recovery | E38: Handle security incidents and restore service. | F38: Ad-hoc response; documentation lacking. | G38: Runbooks exist; responders follow manually. | H38: Orchestration coordinates tasks, communication channels. | I38: AI suggests containment actions, collects evidence automatically. | J38: Agents contain, eradicate, restore services autonomously. | K38: L3 – Orchestrated | M38: L4 – Automated | N38: Deploy Centralized Security Monitoring and Threat Detection Tools | O38: SOAR platforms, IR coordination tools | P38: PagerDuty, ServiceNow IR, Splunk SOAR, IBM Resilient, Cortex XSOAR
C39: OM.03 | D39: Vulnerability Management & Patching | E39: Identify, prioritize, and fix vulnerabilities in applications and underlying operating systems. | F39: Patching done ad-hoc. | G39: Spreadsheet tracks vulnerabilities; manual updates. | H39: Toolchain orchestrates scans, ticketing, scheduling. | I39: AI prioritizes based on risk, automates patch deployment. | J39: Agents predict vulnerabilities, patch proactively before disclosure. | K39: L2 – Assisted | M39: L4 – Automated | N39: Integrate Patch Management & Vulnerability Scanning Automation | O39: VM platforms, patch management tools | P39: Qualys VMDR, Rapid7 InsightVM, Tenable.sc, WSUS
C40: OM.04 | D40: API Security | E40: Securely deploy and monitor API gateways. | F40: Ad-hoc endpoints, no inventory; security issues found post-incident. | G40: API inventory spreadsheet; developers follow an “OWASP API Top 10” checklist before release. | H40: CI pipeline runs contract linting; gateway enforces authN/Z and rate limits. | I40: API discovery keeps inventory current; inline WAF/WAAP adapts rules; automated regression tests. | J40: AI agents correlate traffic anomalies, isolate suspicious tokens, and push mitigations. | K40: L1 – Manual | M40: L2 – Assisted | N40: Deploy Centralized Security Monitoring and Threat Detection Tools | O40: API security, API discovery platforms | P40: Salt Security, Akamai API Security, Cloudflare API Shield
C41: OM.05 | D41: Environment Management & Configuration | E41: Maintain secure configs across environments. | F41: Configurations disparate with unmanaged drift. | G41: Scripts apply configs; drift checked monthly. | H41: Pipeline enforces desired state across environments. | I41: Telemetry detects drift, remediates automatically. | J41: Agents optimize configurations continuously, adapt to workload. | K41: L2 – Assisted | M41: L3 – Orchestrated | N41: Integrate Patch Management & Vulnerability Scanning Automation | O41: Config mgmt & drift detection tools | P41: Chef InSpec, AWS Config, Azure Policy, Puppet
C42: OM.06 | D42: Vulnerability Disclosure & Bug Bounty | E42: Receive and reward external vulnerability reports. | F42: No disclosure channels; ad-hoc emails. | G42: Public email with manual triage, rewards rare. | H42: Managed platform orchestrates intake and response. | I42: AI prioritizes reports, auto-assigns fixes. | J42: Agents engage researchers, validate, patch within hours. | K42: L5 – Autonomous | M42: L5 – Autonomous | N42: Launch Responsible Disclosure & Bug Bounty Program | O42: VDP platforms, bounty coordination | P42: HackerOne, Bugcrowd, OpenBugBounty, Intigriti
C43: OM.07 | D43: Agentic AI Oversight & Control | E43: Govern autonomous AI agent actions and ethics. | F43: AI agents uncontrolled; manual audits sporadic. | G43: Checklists review agent actions periodically. | H43: Workflow logs agent decisions with risk gate approvals. | I43: AI monitors agents, escalates anomalous behavior. | J43: Autonomous governance aligns agents with ethics continuously. | K43: L2 – Assisted | M43: L3 – Orchestrated | N43: Develop AI Risk Governance Framework | O43: AI governance, policy enforcement platforms | P43: Protect AI, Robust Intelligence, OpenAI Moderation API, NVIDIA Morpheus

Sheet 5. Initiative List
B2: Initiative List
B3: Use this tab to define initiatives based on the gap closure actions identified in Tab 4, as follows: 1. When you first identify a gap closure action as being an initiative, enter the initiative name in the table below. 2. Use the drop-down list in column N of Tab 4 to select the initiative. Do this for all gap closure actions that you wish to associate with this initiative. 3. Enter a description of the initiative below or alternatively provide a list of all of the gap closure actions. - You can easily obtain a list of all gap closure actions associated with an initiative by filtering column N on Tab 4.
B5: # | C5: Initiative Name | D5: Description/List of Supporting Actions (Optional)
B6: 1 | C6: Implement Secure SDLC Requirements Gathering Templates
B7: 2 | C7: Deploy Threat Modeling Automation Tools (e.g. ThreatSpec, IriusRisk)
B8: 3 | C8: Establish Secure Architecture Review Board
B9: 4 | C9: Implement Secure AI/ML Design Controls & Data Lineage Tracking
B10: 5 | C10: Train Developers on Secure Coding Practices (OWASP Top 10)
B11: 6 | C11: Integrate SAST Tools Into CI Pipeline
B12: 7 | C12: Automate Software Composition Analysis & Supply Chain Scanning
B13: 8 | C13: Enhance CI/CD Pipelines With Secrets Scanning & Signing Tools
B14: 9 | C14: Implement IaC and Container Security Scanning
B15: 10 | C15: Adopt Policy-as-Code for Automated Security Governance
B16: 11 | C16: Establish Fuzzing and Red Team Engagement Programs
B17: 12 | C17: Deploy Centralized Security Monitoring and Threat Detection Tools
... B20: 15 | C20: Develop AI Risk Governance Framework
B21: 16
B22: 17
B23: 18
B24: 19
B25: 20
B26: 21
B27: 22
B28: 23
B29: 24
B30: 25
B31: 26
B32: 27
... B45: 40

Sheet 6. Prioritization
B2: Initiative Prioritization
B3: Refer to the instructions to the right to complete a cost-benefit analysis for each initiative. Use the cost-benefit analysis to assign a roadmap wave, and optionally a sub-wave, to help plan your road. | D3: For each of the initiatives listed, complete the cost and benefit estimations using the drop-down lists provided. You may optionally add more detailed estimates, if known, in columns P-S. The Alignment With Business benefit will be automatically populated, but you can override the formula by manually selecting from the drop-down list. Optionally add dependency and business impact information if they will be helpful for prioritization.
D4: ="High " & '2. Setup'!E9 & CHAR(10) & "Medium " & '2. Setup'!E10 & CHAR(10) & "Low " & '2. Setup'!E11 -> High >$100K Medium $10K-$100K Low <$10,000 | E4: ="High " & '2. Setup'!E12 & CHAR(10) & "Medium " & '2. Setup'!E13 & CHAR(10) & "Low " & '2. Setup'!E14 -> High >$100K Medium $10K-$100K Low <$10,000 | F4: ="High " & '2. Setup'!E15 & CHAR(10) & "Medium " & '2. Setup'!E16 & CHAR(10) & "Low " & '2. Setup'!E17 -> High >160 Hours Medium 40-160 Hours Low <40 Hours | G4: ="High " & '2. Setup'!E18 & CHAR(10) & "Medium " & '2. Setup'!E19 & CHAR(10) & "Low " & '2. Setup'!E20 -> High >0.5 FTE Medium 0.1-0.5 FTE Low <0.1 FTE | N4: Wave 0 = In-flight Wave 1 = Must do Wave 2 = Should do Wave 3 = Could do Wave 4 = Won't do
D5: Estimated Cost | F5: Estimated Effort | I5: Estimated Benefits | L5: Additional Considerations (Optional) | P5: Detailed Cost Estimates (Optional) | R5: Detailed Staffing Estimates (Optional)
B6: # | C6: Initiative Name | D6: Initial Cost | E6: Ongoing Cost | F6: Initial Staffing | G6: Ongoing Staffing | H6: Cost/Effort Rating | I6: Business Opportunity Alignment | J6: Security Threat Mitigation | K6: Benefit Rating | L6: Dependencies | M6: Business Impacts | N6: Roadmap Wave | O6: Roadmap Sub-Wave (Optional) | P6: Initial Cost | Q6: Ongoing Cost | R6: Initial Staffing (Hours) | S6: Ongoing Staffing (FTEs)
B7: 1 | C7: =IF('5. Initiative List'!C6 = "", "", '5. Initiative List'!C6) -> Implement Secure SDLC Requirements Gathering Templates | D7: Low | E7: Medium | F7: High | G7: High | H7: =IFERROR( SUM(VLOOKUP(D7,'9. List & Calc'!$E$159:$G$162,2,FALSE),VLOOKUP(E7,'9. List & Calc'!$E$164:$F$168,2,FALSE),VLOOKUP('6. Prioritization'!F7,'9. List & Calc'!$E$171:$F$174,2,FALSE),VLOOKUP('6. Prioritization'!G7,'9. List & Calc'!$E$177:$F$180,2,FALSE)), "") -> 9 | I7: =IF(C7="", "", '9. List & Calc'!F183) -> High - Supports multiple priority opportunities | J7: =IF(C7="", "", '9. List & Calc'!G183) -> High - Mitigates multiple priority threats | K7: =IFERROR( SUM(VLOOKUP(I7,'9. List & Calc'!$F$149:$G$151,2,FALSE),VLOOKUP(J7,'9. List & Calc'!$F$154:$G$156,2,FALSE)), "") -> 6 | N7: 1 | P7: =IF(D7="", "", VLOOKUP(D7, '9. List & Calc'!$E$159:$G$162, 3, FALSE)) -> 5000 | Q7: =IF(E7="", "", VLOOKUP(E7, '9. List & Calc'!$E$165:$G$168, 3, FALSE)) -> 50000 | R7: =IF(F7="", "", VLOOKUP(F7, '9. List & Calc'!$E$171:$G$174, 3, FALSE)) -> 240 | S7: =IF(G7="", "", VLOOKUP(G7, '9. List & Calc'!$E$177:$G$180, 3, FALSE)) -> 0.5
B8: 2 | C8: =IF('5. Initiative List'!C7 = "", "", '5. Initiative List'!C7) -> Deploy Threat Modeling Automation Tools (e.g. ThreatSpec, IriusRisk) | D8: Zero | E8: Zero | F8: Medium | G8: Medium | H8: =IFERROR( SUM(VLOOKUP(D8,'9. List & Calc'!$E$159:$G$162,2,FALSE),VLOOKUP(E8,'9. List & Calc'!$E$164:$F$168,2,FALSE),VLOOKUP('6. Prioritization'!F8,'9. List & Calc'!$E$171:$F$174,2,FALSE),VLOOKUP('6. Prioritization'!G8,'9. List & Calc'!$E$177:$F$180,2,FALSE)), "") -> 4 | I8: =IF(C8="", "", '9. List & Calc'!F184) -> Low - Other | J8: =IF(C8="", "", '9. List & Calc'!G184) -> Low - Foundational good practice | K8: =IFERROR( SUM(VLOOKUP(I8,'9. List & Calc'!$F$149:$G$151,2,FALSE),VLOOKUP(J8,'9. List & Calc'!$F$154:$G$156,2,FALSE)), "") -> 2 | N8: 1 | P8: =IF(D8="", "", VLOOKUP(D8, '9. List & Calc'!$E$159:$G$162, 3, FALSE)) -> 0 | Q8: =IF(E8="", "", VLOOKUP(E8, '9. List & Calc'!$E$165:$G$168, 3, FALSE)) -> 0 | R8: =IF(F8="", "", VLOOKUP(F8, '9. List & Calc'!$E$171:$G$174, 3, FALSE)) -> 120 | S8: =IF(G8="", "", VLOOKUP(G8, '9. List & Calc'!$E$177:$G$180, 3, FALSE)) -> 0.25
B9: 3 | C9: =IF('5. Initiative List'!C8 = "", "", '5. Initiative List'!C8) -> Establish Secure Architecture Review Board | D9: Low | E9: Low | F9: High | G9: High | H9: =IFERROR( SUM(VLOOKUP(D9,'9. List & Calc'!$E$159:$G$162,2,FALSE),VLOOKUP(E9,'9. List & Calc'!$E$164:$F$168,2,FALSE),VLOOKUP('6. Prioritization'!F9,'9. List & Calc'!$E$171:$F$174,2,FALSE),VLOOKUP('6. Prioritization'!G9,'9. List & Calc'!$E$177:$F$180,2,FALSE)), "") -> 8 | I9: =IF(C9="", "", '9. List & Calc'!F185) -> High - Supports multiple priority opportunities | J9: =IF(C9="", "", '9. List & Calc'!G185) -> High - Mitigates multiple priority threats | K9: =IFERROR( SUM(VLOOKUP(I9,'9. List & Calc'!$F$149:$G$151,2,FALSE),VLOOKUP(J9,'9. List & Calc'!$F$154:$G$156,2,FALSE)), "") -> 6 | N9: 2 | P9: =IF(D9="", "", VLOOKUP(D9, '9. List & Calc'!$E$159:$G$162, 3, FALSE)) -> 5000 | Q9: =IF(E9="", "", VLOOKUP(E9, '9. List & Calc'!$E$165:$G$168, 3, FALSE)) -> 5000 | R9: =IF(F9="", "", VLOOKUP(F9, '9. List & Calc'!$E$171:$G$174, 3, FALSE)) -> 240 | S9: =IF(G9="", "", VLOOKUP(G9, '9. List & Calc'!$E$177:$G$180, 3, FALSE)) -> 0.5
B10: 4 | C10: =IF('5. Initiative List'!C9 = "", "", '5. Initiative List'!C9) -> Implement Secure AI/ML Design Controls & Data Lineage Tracking | D10: Medium | E10: Medium | F10: Medium | G10: Medium | H10: =IFERROR( SUM(VLOOKUP(D10,'9. List & Calc'!$E$159:$G$162,2,FALSE),VLOOKUP(E10,'9. List & Calc'!$E$164:$F$168,2,FALSE),VLOOKUP('6. Prioritization'!F10,'9. List & Calc'!$E$171:$F$174,2,FALSE),VLOOKUP('6. Prioritization'!G10,'9. List & Calc'!$E$177:$F$180,2,FALSE)), "") -> 8 | I10: =IF(C10="", "", '9. List & Calc'!F186) -> Low - Other | J10: =IF(C10="", "", '9. List & Calc'!G186) -> Low - Foundational good practice | K10: =IFERROR( SUM(VLOOKUP(I10,'9. List & Calc'!$F$149:$G$151,2,FALSE),VLOOKUP(J10,'9. List & Calc'!$F$154:$G$156,2,FALSE)), "") -> 2 | N10: 3 | P10: =IF(D10="", "", VLOOKUP(D10, '9. List & Calc'!$E$159:$G$162, 3, FALSE)) -> 50000 | Q10: =IF(E10="", "", VLOOKUP(E10, '9. List & Calc'!$E$165:$G$168, 3, FALSE)) -> 50000 | R10: =IF(F10="", "", VLOOKUP(F10, '9. List & Calc'!$E$171:$G$174, 3, FALSE)) -> 120 | S10: =IF(G10="", "", VLOOKUP(G10, '9. List & Calc'!$E$177:$G$180, 3, FALSE)) -> 0.25
B11: 5 | C11: =IF('5. Initiative List'!C10 = "", "", '5. Initiative List'!C10) -> Train Developers on Secure Coding Practices (OWASP Top 10) | D11: Low | E11: Low | F11: Medium | G11: Medium | H11: =IFERROR( SUM(VLOOKUP(D11,'9. List & Calc'!$E$159:$G$162,2,FALSE),VLOOKUP(E11,'9. List & Calc'!$E$164:$F$168,2,FALSE),VLOOKUP('6. Prioritization'!F11,'9. List & Calc'!$E$171:$F$174,2,FALSE),VLOOKUP('6. Prioritization'!G11,'9. List & Calc'!$E$177:$F$180,2,FALSE)), "") -> 6 | I11: =IF(C11="", "", '9. List & Calc'!F187) -> High - Supports multiple priority opportunities | J11: =IF(C11="", "", '9. List & Calc'!G187) -> High - Mitigates multiple priority threats | K11: =IFERROR( SUM(VLOOKUP(I11,'9. List & Calc'!$F$149:$G$151,2,FALSE),VLOOKUP(J11,'9. List & Calc'!$F$154:$G$156,2,FALSE)), "") -> 6 | N11: 4 | P11: =IF(D11="", "", VLOOKUP(D11, '9. List & Calc'!$E$159:$G$162, 3, FALSE)) -> 5000 | Q11: =IF(E11="", "", VLOOKUP(E11, '9. List & Calc'!$E$165:$G$168, 3, FALSE)) -> 5000 | R11: =IF(F11="", "", VLOOKUP(F11, '9. List & Calc'!$E$171:$G$174, 3, FALSE)) -> 120 | S11: =IF(G11="", "", VLOOKUP(G11, '9. List & Calc'!$E$177:$G$180, 3, FALSE)) -> 0.25
B12: 6 | C12: =IF('5. Initiative List'!C11 = "", "", '5. Initiative List'!C11) -> Integrate SAST Tools Into CI Pipeline | D12: Medium | E12: Low | F12: Low | G12: Low | H12: =IFERROR( SUM(VLOOKUP(D12,'9. List & Calc'!$E$159:$G$162,2,FALSE),VLOOKUP(E12,'9. List & Calc'!$E$164:$F$168,2,FALSE),VLOOKUP('6. Prioritization'!F12,'9. List & Calc'!$E$171:$F$174,2,FALSE),VLOOKUP('6. Prioritization'!G12,'9. List & Calc'!$E$177:$F$180,2,FALSE)), "") -> 5 | I12: =IF(C12="", "", '9. List & Calc'!F188) -> High - Supports multiple priority opportunities | J12: =IF(C12="", "", '9. List & Calc'!G188) -> High - Mitigates multiple priority threats | K12: =IFERROR( SUM(VLOOKUP(I12,'9. List & Calc'!$F$149:$G$151,2,FALSE),VLOOKUP(J12,'9. List & Calc'!$F$154:$G$156,2,FALSE)), "") -> 6 | N12: 3 | P12: =IF(D12="", "", VLOOKUP(D12, '9. List & Calc'!$E$159:$G$162, 3, FALSE)) -> 50000 | Q12: =IF(E12="", "", VLOOKUP(E12, '9. List & Calc'!$E$165:$G$168, 3, FALSE)) -> 5000 | R12: =IF(F12="", "", VLOOKUP(F12, '9. List & Calc'!$E$171:$G$174, 3, FALSE)) -> 30 | S12: =IF(G12="", "", VLOOKUP(G12, '9. List & Calc'!$E$177:$G$180, 3, FALSE)) -> 0.05
B13: 7 | C13: =IF('5. Initiative List'!C12 = "", "", '5. Initiative List'!C12) -> Automate Software Composition Analysis & Supply Chain Scanning | D13: High | E13: Medium | F13: Medium | G13: Low | H13: =IFERROR( SUM(VLOOKUP(D13,'9. List & Calc'!$E$159:$G$162,2,FALSE),VLOOKUP(E13,'9. List & Calc'!$E$164:$F$168,2,FALSE),VLOOKUP('6. Prioritization'!F13,'9. List & Calc'!$E$171:$F$174,2,FALSE),VLOOKUP('6. Prioritization'!G13,'9. List & Calc'!$E$177:$F$180,2,FALSE)), "") -> 8 | I13: =IF(C13="", "", '9. List & Calc'!F189) -> Medium - Supports a priority opportunity | J13: =IF(C13="", "", '9. List & Calc'!G189) -> Low - Foundational good practice | K13: =IFERROR( SUM(VLOOKUP(I13,'9. List & Calc'!$F$149:$G$151,2,FALSE),VLOOKUP(J13,'9. List & Calc'!$F$154:$G$156,2,FALSE)), "") -> 3 | N13: 4 | P13: =IF(D13="", "", VLOOKUP(D13, '9. List & Calc'!$E$159:$G$162, 3, FALSE)) -> 120000 | Q13: =IF(E13="", "", VLOOKUP(E13, '9. List & Calc'!$E$165:$G$168, 3, FALSE)) -> 50000 | R13: =IF(F13="", "", VLOOKUP(F13, '9. List & Calc'!$E$171:$G$174, 3, FALSE)) -> 120 | S13: =IF(G13="", "", VLOOKUP(G13, '9. List & Calc'!$E$177:$G$180, 3, FALSE)) -> 0.05
B14: 8 | C14: =IF('5. Initiative List'!C13 = "", "", '5. Initiative List'!C13) -> Enhance CI/CD Pipelines With Secrets Scanning & Signing Tools | D14: Medium | E14: Low | F14: Medium | G14: Low | H14: =IFERROR( SUM(VLOOKUP(D14,'9. List & Calc'!$E$159:$G$162,2,FALSE),VLOOKUP(E14,'9. List & Calc'!$E$164:$F$168,2,FALSE),VLOOKUP('6. Prioritization'!F14,'9. List & Calc'!$E$171:$F$174,2,FALSE),VLOOKUP('6. Prioritization'!G14,'9. List & Calc'!$E$177:$F$180,2,FALSE)), "") -> 6 | I14: =IF(C14="", "", '9. List & Calc'!F190) -> High - Supports multiple priority opportunities | J14: =IF(C14="", "", '9. List & Calc'!G190) -> High - Mitigates multiple priority threats | K14: =IFERROR( SUM(VLOOKUP(I14,'9. List & Calc'!$F$149:$G$151,2,FALSE),VLOOKUP(J14,'9. List & Calc'!$F$154:$G$156,2,FALSE)), "") -> 6 | N14: 2 | P14: =IF(D14="", "", VLOOKUP(D14, '9. List & Calc'!$E$159:$G$162, 3, FALSE)) -> 50000 | Q14: =IF(E14="", "", VLOOKUP(E14, '9. List & Calc'!$E$165:$G$168, 3, FALSE)) -> 5000 | R14: =IF(F14="", "", VLOOKUP(F14, '9. List & Calc'!$E$171:$G$174, 3, FALSE)) -> 120 | S14: =IF(G14="", "", VLOOKUP(G14, '9. List & Calc'!$E$177:$G$180, 3, FALSE)) -> 0.05
B15: 9 | C15: =IF('5. Initiative List'!C14 = "", "", '5. Initiative List'!C14) -> Implement IaC and Container Security Scanning | D15: Low | E15: Low | F15: Low | G15: Zero | H15: =IFERROR( SUM(VLOOKUP(D15,'9. List & Calc'!$E$159:$G$162,2,FALSE),VLOOKUP(E15,'9. List & Calc'!$E$164:$F$168,2,FALSE),VLOOKUP('6. Prioritization'!F15,'9. List & Calc'!$E$171:$F$174,2,FALSE),VLOOKUP('6. Prioritization'!G15,'9. List & Calc'!$E$177:$F$180,2,FALSE)), "") -> 3 | I15: =IF(C15="", "", '9. List & Calc'!F191) -> Medium - Supports a priority opportunity | J15: =IF(C15="", "", '9. List & Calc'!G191) -> Low - Foundational good practice | K15: =IFERROR( SUM(VLOOKUP(I15,'9. List & Calc'!$F$149:$G$151,2,FALSE),VLOOKUP(J15,'9. List & Calc'!$F$154:$G$156,2,FALSE)), "") -> 3 | N15: 4 | P15: =IF(D15="", "", VLOOKUP(D15, '9. List & Calc'!$E$159:$G$162, 3, FALSE)) -> 5000 | Q15: =IF(E15="", "", VLOOKUP(E15, '9. List & Calc'!$E$165:$G$168, 3, FALSE)) -> 5000 | R15: =IF(F15="", "", VLOOKUP(F15, '9. List & Calc'!$E$171:$G$174, 3, FALSE)) -> 30 | S15: =IF(G15="", "", VLOOKUP(G15, '9. List & Calc'!$E$177:$G$180, 3, FALSE)) -> 0
B16: 10 | C16: =IF('5. Initiative List'!C15 = "", "", '5. Initiative List'!C15) -> Adopt Policy-as-Code for Automated Security Governance | D16: High | E16: Low | F16: Medium | G16: Low | H16: =IFERROR( SUM(VLOOKUP(D16,'9. List & Calc'!$E$159:$G$162,2,FALSE),VLOOKUP(E16,'9. List & Calc'!$E$164:$F$168,2,FALSE),VLOOKUP('6. Prioritization'!F16,'9. List & Calc'!$E$171:$F$174,2,FALSE),VLOOKUP('6. Prioritization'!G16,'9. List & Calc'!$E$177:$F$180,2,FALSE)), "") -> 7 | I16: =IF(C16="", "", '9. List & Calc'!F192) -> High - Supports multiple priority opportunities | J16: =IF(C16="", "", '9. List & Calc'!G192) -> Medium - Mitigates a priority threat | K16: =IFERROR( SUM(VLOOKUP(I16,'9. List & Calc'!$F$149:$G$151,2,FALSE),VLOOKUP(J16,'9. List & Calc'!$F$154:$G$156,2,FALSE)), "") -> 5 | N16: 3 | P16: =IF(D16="", "", VLOOKUP(D16, '9. List & Calc'!$E$159:$G$162, 3, FALSE)) -> 120000 | Q16: =IF(E16="", "", VLOOKUP(E16, '9. List & Calc'!$E$165:$G$168, 3, FALSE)) -> 5000 | R16: =IF(F16="", "", VLOOKUP(F16, '9. List & Calc'!$E$171:$G$174, 3, FALSE)) -> 120 | S16: =IF(G16="", "", VLOOKUP(G16, '9. List & Calc'!$E$177:$G$180, 3, FALSE)) -> 0.05
B17: 11 | C17: =IF('5. Initiative List'!C16 = "", "", '5. Initiative List'!C16) -> Establish Fuzzing and Red Team Engagement Programs | D17: Medium | E17: Medium | F17: Medium | G17: Low | H17: =IFERROR( SUM(VLOOKUP(D17,'9. List & Calc'!$E$159:$G$162,2,FALSE),VLOOKUP(E17,'9. List & Calc'!$E$164:$F$168,2,FALSE),VLOOKUP('6. Prioritization'!F17,'9. List & Calc'!$E$171:$F$174,2,FALSE),VLOOKUP('6. Prioritization'!G17,'9. List & Calc'!$E$177:$F$180,2,FALSE)), "") -> 7 | I17: =IF(C17="", "", '9. List & Calc'!F193) -> Medium - Supports a priority opportunity | J17: =IF(C17="", "", '9. List & Calc'!G193) -> High - Mitigates multiple priority threats | K17: =IFERROR( SUM(VLOOKUP(I17,'9. List & Calc'!$F$149:$G$151,2,FALSE),VLOOKUP(J17,'9. List & Calc'!$F$154:$G$156,2,FALSE)), "") -> 5 | N17: 2 | P17: =IF(D17="", "", VLOOKUP(D17, '9. List & Calc'!$E$159:$G$162, 3, FALSE)) -> 50000 | Q17: =IF(E17="", "", VLOOKUP(E17, '9. List & Calc'!$E$165:$G$168, 3, FALSE)) -> 50000 | R17: =IF(F17="", "", VLOOKUP(F17, '9. List & Calc'!$E$171:$G$174, 3, FALSE)) -> 120 | S17: =IF(G17="", "", VLOOKUP(G17, '9. List & Calc'!$E$177:$G$180, 3, FALSE)) -> 0.05
B18: 12 | C18: =IF('5. Initiative List'!C17 = "", "", '5. Initiative List'!C17) -> Deploy Centralized Security Monitoring and Threat Detection Tools | D18: High | E18: High | F18: High | G18: High | H18: =IFERROR( SUM(VLOOKUP(D18,'9. List & Calc'!$E$159:$G$162,2,FALSE),VLOOKUP(E18,'9. List & Calc'!$E$164:$F$168,2,FALSE),VLOOKUP('6. Prioritization'!F18,'9. List & Calc'!$E$171:$F$174,2,FALSE),VLOOKUP('6. Prioritization'!G18,'9. List & Calc'!$E$177:$F$180,2,FALSE)), "") -> 12 | I18: =IF(C18="", "", '9. List & Calc'!F194) -> High - Supports multiple priority opportunities | J18: =IF(C18="", "", '9. List & Calc'!G194) -> High - Mitigates multiple priority threats | K18: =IFERROR( SUM(VLOOKUP(I18,'9. List & Calc'!$F$149:$G$151,2,FALSE),VLOOKUP(J18,'9. List & Calc'!$F$154:$G$156,2,FALSE)), "") -> 6 | N18: 2 | P18: =IF(D18="", "", VLOOKUP(D18, '9. List & Calc'!$E$159:$G$162, 3, FALSE)) -> 120000 | Q18: =IF(E18="", "", VLOOKUP(E18, '9. List & Calc'!$E$165:$G$168, 3, FALSE)) -> 120000 | R18: =IF(F18="", "", VLOOKUP(F18, '9. List & Calc'!$E$171:$G$174, 3, FALSE)) -> 240 | S18: =IF(G18="", "", VLOOKUP(G18, '9. List & Calc'!$E$177:$G$180, 3, FALSE)) -> 0.5
... B21: 15 | C21: =IF('5. Initiative List'!C20 = "", "", '5. Initiative List'!C20) -> Develop AI Risk Governance Framework | D21: Low | E21: Low | F21: Medium | G21: Medium | H21: =IFERROR( SUM(VLOOKUP(D21,'9. List & Calc'!$E$159:$G$162,2,FALSE),VLOOKUP(E21,'9. List & Calc'!$E$164:$F$168,2,FALSE),VLOOKUP('6. Prioritization'!F21,'9. List & Calc'!$E$171:$F$174,2,FALSE),VLOOKUP('6. Prioritization'!G21,'9. List & Calc'!$E$177:$F$180,2,FALSE)), "") -> 6 | I21: =IF(C21="", "", '9. List & Calc'!F197) -> Low - Other | J21: =IF(C21="", "", '9. List & Calc'!G197) -> Low - Foundational good practice | K21: =IFERROR( SUM(VLOOKUP(I21,'9. List & Calc'!$F$149:$G$151,2,FALSE),VLOOKUP(J21,'9. List & Calc'!$F$154:$G$156,2,FALSE)), "") -> 2 | N21: 4 | P21: =IF(D21="", "", VLOOKUP(D21, '9. List & Calc'!$E$159:$G$162, 3, FALSE)) -> 5000 | Q21: =IF(E21="", "", VLOOKUP(E21, '9. List & Calc'!$E$165:$G$168, 3, FALSE)) -> 5000 | R21: =IF(F21="", "", VLOOKUP(F21, '9. List & Calc'!$E$171:$G$174, 3, FALSE)) -> 120 | S21: =IF(G21="", "", VLOOKUP(G21, '9. List & Calc'!$E$177:$G$180, 3, FALSE)) -> 0.25
B22: 16 | C22: =IF('5. Initiative List'!C21 = "", "", '5. Initiative List'!C21) | H22: =IFERROR( SUM(VLOOKUP(D22,'9. List & Calc'!$E$159:$G$162,2,FALSE),VLOOKUP(E22,'9. List & Calc'!$E$164:$F$168,2,FALSE),VLOOKUP('6. Prioritization'!F22,'9. List & Calc'!$E$171:$F$174,2,FALSE),VLOOKUP('6. Prioritization'!G22,'9. List & Calc'!$E$177:$F$180,2,FALSE)), "") | I22: =IF(C22="", "", '9. List & Calc'!F198) | J22: =IF(C22="", "", '9. List & Calc'!G198) | K22: =IFERROR( SUM(VLOOKUP(I22,'9. List & Calc'!$F$149:$G$151,2,FALSE),VLOOKUP(J22,'9. List & Calc'!$F$154:$G$156,2,FALSE)), "") | P22: =IF(D22="", "", VLOOKUP(D22, '9. List & Calc'!$E$159:$G$162, 3, FALSE)) | Q22: =IF(E22="", "", VLOOKUP(E22, '9. List & Calc'!$E$165:$G$168, 3, FALSE)) | R22: =IF(F22="", "", VLOOKUP(F22, '9. List & Calc'!$E$171:$G$174, 3, FALSE)) | S22: =IF(G22="", "", VLOOKUP(G22, '9. List & Calc'!$E$177:$G$180, 3, FALSE))
B23: 17 | C23: =IF('5. Initiative List'!C22 = "", "", '5. Initiative List'!C22) | H23: =IFERROR( SUM(VLOOKUP(D23,'9. List & Calc'!$E$159:$G$162,2,FALSE),VLOOKUP(E23,'9. List & Calc'!$E$164:$F$168,2,FALSE),VLOOKUP('6. Prioritization'!F23,'9. List & Calc'!$E$171:$F$174,2,FALSE),VLOOKUP('6. Prioritization'!G23,'9. List & Calc'!$E$177:$F$180,2,FALSE)), "") | I23: =IF(C23="", "", '9. List & Calc'!F199) | J23: =IF(C23="", "", '9. List & Calc'!G199) | K23: =IFERROR( SUM(VLOOKUP(I23,'9. List & Calc'!$F$149:$G$151,2,FALSE),VLOOKUP(J23,'9. List & Calc'!$F$154:$G$156,2,FALSE)), "") | P23: =IF(D23="", "", VLOOKUP(D23, '9. List & Calc'!$E$159:$G$162, 3, FALSE)) | Q23: =IF(E23="", "", VLOOKUP(E23, '9. List & Calc'!$E$165:$G$168, 3, FALSE)) | R23: =IF(F23="", "", VLOOKUP(F23, '9. List & Calc'!$E$171:$G$174, 3, FALSE)) | S23: =IF(G23="", "", VLOOKUP(G23, '9. List & Calc'!$E$177:$G$180, 3, FALSE))
